<?xml version="1.0" encoding="utf-8"?>
<!-- This URDF was automatically created by SolidWorks to URDF Exporter! Originally created by Stephen Brawner (brawner@gmail.com) 
     Commit Version: 1.6.0-4-g7f85cfe  Build Version: 1.6.7995.38578
     For more information, please see http://wiki.ros.org/sw_urdf_exporter -->
<robot
  name="dd">
  <link
    name="base_link">
    <inertial>
      <origin
        xyz="0.00013693 0.0050257 -1.8097E-17"
        rpy="0 0 0" />
      <mass
        value="0.60226" />
      <inertia
        ixx="0.0020245"
        ixy="-1.8534E-06"
        ixz="-8.1229E-19"
        iyy="0.0065516"
        iyz="8.5205E-20"
        izz="0.0045379" />
    </inertial>
    <visual>
      <origin
        xyz="0 0 0"
        rpy="0 0 0" />
      <geometry>
        <mesh
          filename="package://dd/meshes/base_link.STL" />
      </geometry>
      <material
        name="">
        <color
          rgba="0.79216 0.81961 0.93333 1" />
      </material>
    </visual>
    <collision>
      <origin
        xyz="0 0 0"
        rpy="0 0 0" />
      <geometry>
        <mesh
          filename="package://dd/meshes/base_link.STL" />
      </geometry>
    </collision>
  </link>
  <link
    name="flw">
    <inertial>
      <origin
        xyz="-2.6021E-18 -0.0025 -2.7756E-17"
        rpy="0 0 0" />
      <mass
        value="0.013959" />
      <inertia
        ixx="3.1739E-06"
        ixy="3.8315E-35"
        ixz="-1.5293E-38"
        iyy="6.2902E-06"
        iyz="1.5125E-39"
        izz="3.1739E-06" />
    </inertial>
    <visual>
      <origin
        xyz="0 0 0"
        rpy="0 0 0" />
      <geometry>
        <mesh
          filename="package://dd/meshes/flw.STL" />
      </geometry>
      <material
        name="">
        <color
          rgba="0.79216 0.81961 0.93333 1" />
      </material>
    </visual>
    <collision>
      <origin
        xyz="0 0 0"
        rpy="0 0 0" />
      <geometry>
        <mesh
          filename="package://dd/meshes/flw.STL" />
      </geometry>
    </collision>
  </link>
  <joint
    name="flw_j"
    type="continuous">
    <origin
      xyz="0.12 0.115 0.005"
      rpy="0 -1.5708 0" />
    <parent
      link="base_link" />
    <child
      link="flw" />
    <axis
      xyz="0 1 0" />
  </joint>
  <link
    name="rlw">
    <inertial>
      <origin
        xyz="-2.6021E-18 -0.0025 -1.3878E-17"
        rpy="0 0 0" />
      <mass
        value="0.013959" />
      <inertia
        ixx="3.1739E-06"
        ixy="3.8314E-35"
        ixz="1.5288E-38"
        iyy="6.2902E-06"
        iyz="1.5125E-39"
        izz="3.1739E-06" />
    </inertial>
    <visual>
      <origin
        xyz="0 0 0"
        rpy="0 0 0" />
      <geometry>
        <mesh
          filename="package://dd/meshes/rlw.STL" />
      </geometry>
      <material
        name="">
        <color
          rgba="0.79216 0.81961 0.93333 1" />
      </material>
    </visual>
    <collision>
      <origin
        xyz="0 0 0"
        rpy="0 0 0" />
      <geometry>
        <mesh
          filename="package://dd/meshes/rlw.STL" />
      </geometry>
    </collision>
  </link>
  <joint
    name="rlw_j"
    type="continuous">
    <origin
      xyz="-0.12 0.115 0.005"
      rpy="0 -1.5708 0" />
    <parent
      link="base_link" />
    <child
      link="rlw" />
    <axis
      xyz="0 1 0" />
  </joint>
  <link
    name="rrw">
    <inertial>
      <origin
        xyz="0 0.0025 1.3878E-17"
        rpy="0 0 0" />
      <mass
        value="0.013959" />
      <inertia
        ixx="3.1739E-06"
        ixy="3.8314E-35"
        ixz="5.3379E-39"
        iyy="6.2902E-06"
        iyz="-2.4542E-39"
        izz="3.1739E-06" />
    </inertial>
    <visual>
      <origin
        xyz="0 0 0"
        rpy="0 0 0" />
      <geometry>
        <mesh
          filename="package://dd/meshes/rrw.STL" />
      </geometry>
      <material
        name="">
        <color
          rgba="0.79216 0.81961 0.93333 1" />
      </material>
    </visual>
    <collision>
      <origin
        xyz="0 0 0"
        rpy="0 0 0" />
      <geometry>
        <mesh
          filename="package://dd/meshes/rrw.STL" />
      </geometry>
    </collision>
  </link>
  <joint
    name="rrw_j"
    type="continuous">
    <origin
      xyz="-0.12 -0.115 0.005"
      rpy="0 -1.5708 0" />
    <parent
      link="base_link" />
    <child
      link="rrw" />
    <axis
      xyz="0 1 0" />
  </joint>
  <link
    name="frw">
    <inertial>
      <origin
        xyz="0 0.0025 -1.3878E-17"
        rpy="0 0 0" />
      <mass
        value="0.013959" />
      <inertia
        ixx="3.1739E-06"
        ixy="3.8314E-35"
        ixz="5.3379E-39"
        iyy="6.2902E-06"
        iyz="-1.9848E-39"
        izz="3.1739E-06" />
    </inertial>
    <visual>
      <origin
        xyz="0 0 0"
        rpy="0 0 0" />
      <geometry>
        <mesh
          filename="package://dd/meshes/frw.STL" />
      </geometry>
      <material
        name="">
        <color
          rgba="0.79216 0.81961 0.93333 1" />
      </material>
    </visual>
    <collision>
      <origin
        xyz="0 0 0"
        rpy="0 0 0" />
      <geometry>
        <mesh
          filename="package://dd/meshes/frw.STL" />
      </geometry>
    </collision>
  </link>
  <joint
    name="frw_j"
    type="continuous">
    <origin
      xyz="0.12 -0.115 0.005"
      rpy="0 -1.5708 0" />
    <parent
      link="base_link" />
    <child
      link="frw" />
    <axis
      xyz="0 1 0" />
  </joint>
  <link
    name="lidar">
    <inertial>
      <origin
        xyz="-2.7756E-17 0.0025 -1.4329E-17"
        rpy="0 0 0" />
      <mass
        value="0.00029452" />
      <inertia
        ixx="2.9146E-09"
        ixy="-1.1857E-41"
        ixz="-2.3434E-42"
        iyy="4.6019E-09"
        iyz="-6.8932E-26"
        izz="2.9146E-09" />
    </inertial>
    <visual>
      <origin
        xyz="0 0 0"
        rpy="0 0 0" />
      <geometry>
        <mesh
          filename="package://dd/meshes/lidar.STL" />
      </geometry>
      <material
        name="">
        <color
          rgba="0.79216 0.81961 0.93333 1" />
      </material>
    </visual>
    <collision>
      <origin
        xyz="0 0 0"
        rpy="0 0 0" />
      <geometry>
        <mesh
          filename="package://dd/meshes/lidar.STL" />
      </geometry>
    </collision>
  </link>
  <joint
    name="lidar_j"
    type="fixed">
    <origin
      xyz="0.12 0 0.04"
      rpy="0 0 0" />
    <parent
      link="base_link" />
    <child
      link="lidar" />
    <axis
      xyz="0 0 0" />
  </joint>
  <link
    name="radar">
    <inertial>
      <origin
        xyz="-1.3878E-17 0.0025 -1.4329E-17"
        rpy="0 0 0" />
      <mass
        value="0.00029452" />
      <inertia
        ixx="2.9146E-09"
        ixy="-1.1857E-41"
        ixz="-2.3434E-42"
        iyy="4.6019E-09"
        iyz="-5.1768E-41"
        izz="2.9146E-09" />
    </inertial>
    <visual>
      <origin
        xyz="0 0 0"
        rpy="0 0 0" />
      <geometry>
        <mesh
          filename="package://dd/meshes/radar.STL" />
      </geometry>
      <material
        name="">
        <color
          rgba="0.79216 0.81961 0.93333 1" />
      </material>
    </visual>
    <collision>
      <origin
        xyz="0 0 0"
        rpy="0 0 0" />
      <geometry>
        <mesh
          filename="package://dd/meshes/radar.STL" />
      </geometry>
    </collision>
  </link>
  <joint
    name="radar_j"
    type="fixed">
    <origin
      xyz="0.12 0 0.01"
      rpy="0 0 0" />
    <parent
      link="base_link" />
    <child
      link="radar" />
    <axis
      xyz="0 0 0" />
  </joint>
        <!-- Gazebo plugin for the LIDAR sensor -->
  <gazebo reference="lidar">
    <sensor type="ray" name="head_hokuyo_sensor">
      <pose>0 0 0 0 0 0</pose>
      <visualize>false</visualize>
      <update_rate>40</update_rate>
      <ray>
        <scan>
          <horizontal>
            <samples>720</samples>
            <resolution>1</resolution>
            <min_angle>-3.14</min_angle>
            <max_angle>3.14</max_angle>
          </horizontal>
        </scan>
        <range>
          <min>0.10</min>
          <max>30.0</max>
          <resolution>0.01</resolution>
        </range>
        <noise>
          <type>gaussian</type>
          <!-- Noise parameters based on published spec for Hokuyo laser
               achieving "+-30mm" accuracy at range < 10m.  A mean of 0.0m and
               stddev of 0.01m will put 99.7% of samples within 0.03m of the true
               reading. -->
          <mean>0.0</mean>
          <stddev>0.01</stddev>
        </noise>
      </ray>
      <plugin name="gazebo_ros_head_hokuyo_controller" filename="libgazebo_ros_laser.so">
        <topicName>/laser/scan</topicName>
        <frameName>lidar</frameName>
      </plugin>
    </sensor>
  </gazebo>

  <gazebo>
    <plugin name="differential_drive_controller" filename="libgazebo_ros_diff_drive.so">

      <!-- Plugin update rate in Hz -->
      <updateRate>50</updateRate>

      <!-- Name of left joint, defaults to `left_joint` -->
      <leftJoint>rlw_j</leftJoint>

      <!-- Name of right joint, defaults to `right_joint` -->
      <rightJoint>rrw_j</rightJoint>

      <!-- The distance from the center of one wheel to the other, in meters, defaults to 0.34 m -->
      <wheelSeparation>0.220</wheelSeparation>

      <!-- Diameter of the wheels, in meters, defaults to 0.15 m -->
      <wheelDiameter>0.060</wheelDiameter>

      <!-- Wheel acceleration, in rad/s^2, defaults to 0.0 rad/s^2 -->
      <wheelAcceleration>1.0</wheelAcceleration>

      <!-- Maximum torque which the wheels can produce, in Nm, defaults to 5 Nm -->
      <wheelTorque>20</wheelTorque>

      <!-- Topic to receive geometry_msgs/Twist message commands, defaults to `cmd_vel` -->
      <commandTopic>cmd_vel</commandTopic>

      <!-- Topic to publish nav_msgs/Odometry messages, defaults to `odom` -->
      <odometryTopic>odom</odometryTopic>

      <!-- Odometry frame, defaults to `odom` -->
      <odometryFrame>odom</odometryFrame>

      <!-- Robot frame to calculate odometry from, defaults to `base_footprint` -->
      <robotBaseFrame>base_footprint</robotBaseFrame>

      <!-- Odometry source, 0 for ENCODER, 1 for WORLD, defaults to WORLD -->
      <odometrySource>1</odometrySource>

      <!-- Set to true to publish transforms for the wheel links, defaults to false -->
      <publishWheelTF>true</publishWheelTF>

      <!-- Set to true to publish transforms for the odometry, defaults to true -->
      <publishOdom>true</publishOdom>

      <!-- Set to true to publish sensor_msgs/JointState on /joint_states for the wheel joints, defaults to false -->
      <publishWheelJointState>true</publishWheelJointState>

      <!-- Set to true to swap right and left wheels, defaults to true -->
      <legacyMode>false</legacyMode>
      <!--<robotBaseFrame>base_link</robotBaseFrame>-->
    </plugin>
  </gazebo>

  <gazebo reference="rlw">
    <mu1>0.9</mu1>
    <mu2>0.9</mu2>
  </gazebo>

  <gazebo reference="rrw">
    <mu1>0.9</mu1>
    <mu2>0.9</mu2>
  </gazebo>

  <gazebo reference="flw">
    <mu1>0.9</mu1>
    <mu2>0.9</mu2>
  </gazebo>

  <gazebo reference="frw">
    <mu1>0.9</mu1>
    <mu2>0.9</mu2>
  </gazebo>
</robot>